WARN[0000] /root/.anteon/selfhosted/docker-compose.yml: `version` is obsolete
hammerdebug-1                   | time="2024-07-10T07:55:39Z" level=error msg=hm_heartbeat_err app=hammer ddosifyenv=onprem error_reason="Post \"http://hammermanager:8001/api/hammer/health_check/\": context deadline exceeded (Client.Timeout exceeded while awaiting headers)" id=6b5d415d-4638-4c42-ab39-b64c332ce0f0 ip=127.0.0.1
alaz-backend-celery-beat-1      | psycopg2.errors.UndefinedColumn: column django_celery_beat_periodictask.clocked_id does not exist
alaz-backend-celery-beat-1      |     with self.db.wrap_database_errors:
alaz-backend-celery-beat-1      | psycopg2.errors.UndefinedColumn: column django_celery_beat_periodictask.clocked_id does not exist
alaz-backend-celery-worker-1-1  | 2024-07-10 06:53:53,878 CRITICAL celery.worker Unrecoverable error: OperationalError('[Errno 111] Connection refused')
alaz-backend-celery-worker-1-1  |   File "/usr/local/lib/python3.12/site-packages/kombu/connection.py", line 472, in _reraise_as_library_errors
backend-celery-worker-1         | {"app": "backend", "anteonenv": "onprem", "level": "fatal", "time": "2024-07-10T06:53:54Z", "message": "Traceback (most recent call last):\n  File \"/usr/local/lib/python3.11/site-packages/kombu/connection.py\", line 472, in _reraise_as_library_errors\n    yield\n  File \"/usr/local/lib/python3.11/site-packages/kombu/connection.py\", line 459, in _ensure_connection\n    return retry_over_time(\n           ^^^^^^^^^^^^^^^^\n  File \"/usr/local/lib/python3.11/site-packages/kombu/utils/functional.py\", line 318, in retry_over_time\n    return fun(*args, **kwargs)\n           ^^^^^^^^^^^^^^^^^^^^\n  File \"/usr/local/lib/python3.11/site-packages/kombu/connection.py\", line 934, in _connection_factory\n    self._connection = self._establish_connection()\n                       ^^^^^^^^^^^^^^^^^^^^^^^^^^^^\n  File \"/usr/local/lib/python3.11/site-packages/kombu/connection.py\", line 860, in _establish_connection\n    conn = self.transport.establish_connection()\n           ^^^^^^^^^^^^^^^^^^^^^^^^^^^^^^^^^^^^^\n  File \"/usr/local/lib/python3.11/site-packages/kombu/transport/pyamqp.py\", line 203, in establish_connection\n    conn.connect()\n  File \"/usr/local/lib/python3.11/site-packages/amqp/connection.py\", line 324, in connect\n    self.transport.connect()\n  File \"/usr/local/lib/python3.11/site-packages/amqp/transport.py\", line 129, in connect\n    self._connect(self.host, self.port, self.connect_timeout)\n  File \"/usr/local/lib/python3.11/site-packages/amqp/transport.py\", line 184, in _connect\n    self.sock.connect(sa)\nConnectionRefusedError: [Errno 111] Connection refused\n\nThe above exception was the direct cause of the following exception:\n\nTraceback (most recent call last):\n  File \"/usr/local/lib/python3.11/site-packages/celery/worker/worker.py\", line 202, in start\n    self.blueprint.start(self)\n  File \"/usr/local/lib/python3.11/site-packages/celery/bootsteps.py\", line 112, in start\n    self.on_start()\n  File \"/usr/local/lib/python3.11/site-packages/celery/apps/worker.py\", line 132, in on_start\n    self.purge_messages()\n  File \"/usr/local/lib/python3.11/site-packages/celery/apps/worker.py\", line 187, in purge_messages\n    count = self.app.control.purge(connection=connection)\n            ^^^^^^^^^^^^^^^^^^^^^^^^^^^^^^^^^^^^^^^^^^^^^\n  File \"/usr/local/lib/python3.11/site-packages/celery/app/control.py\", line 467, in purge\n    return self.app.amqp.TaskConsumer(conn).purge()\n           ^^^^^^^^^^^^^^^^^^^^^^^^^^^^^^^^\n  File \"/usr/local/lib/python3.11/site-packages/celery/app/amqp.py\", line 274, in TaskConsumer\n    return self.Consumer(\n           ^^^^^^^^^^^^^^\n  File \"/usr/local/lib/python3.11/site-packages/kombu/messaging.py\", line 402, in __init__\n    self.revive(self.channel)\n  File \"/usr/local/lib/python3.11/site-packages/kombu/messaging.py\", line 415, in revive\n    channel = self.channel = maybe_channel(channel)\n                             ^^^^^^^^^^^^^^^^^^^^^^\n  File \"/usr/local/lib/python3.11/site-packages/kombu/connection.py\", line 1110, in maybe_channel\n    return channel.default_channel\n           ^^^^^^^^^^^^^^^^^^^^^^^\n  File \"/usr/local/lib/python3.11/site-packages/kombu/connection.py\", line 953, in default_channel\n    self._ensure_connection(**conn_opts)\n  File \"/usr/local/lib/python3.11/site-packages/kombu/connection.py\", line 458, in _ensure_connection\n    with ctx():\n  File \"/usr/local/lib/python3.11/contextlib.py\", line 158, in __exit__\n    self.gen.throw(typ, value, traceback)\n  File \"/usr/local/lib/python3.11/site-packages/kombu/connection.py\", line 476, in _reraise_as_library_errors\n    raise ConnectionError(str(exc)) from exc\nkombu.exceptions.OperationalError: [Errno 111] Connection refused"}
hammermanager-celery-worker-1   | {"app": "hm", "ddosifyenv": "onprem", "level": "fatal", "time": "2024-07-10T06:53:50Z", "message": "Traceback (most recent call last):\n  File \"/usr/local/lib/python3.11/site-packages/kombu/connection.py\", line 472, in _reraise_as_library_errors\n    yield\n  File \"/usr/local/lib/python3.11/site-packages/kombu/connection.py\", line 459, in _ensure_connection\n    return retry_over_time(\n           ^^^^^^^^^^^^^^^^\n  File \"/usr/local/lib/python3.11/site-packages/kombu/utils/functional.py\", line 318, in retry_over_time\n    return fun(*args, **kwargs)\n           ^^^^^^^^^^^^^^^^^^^^\n  File \"/usr/local/lib/python3.11/site-packages/kombu/connection.py\", line 934, in _connection_factory\n    self._connection = self._establish_connection()\n                       ^^^^^^^^^^^^^^^^^^^^^^^^^^^^\n  File \"/usr/local/lib/python3.11/site-packages/kombu/connection.py\", line 860, in _establish_connection\n    conn = self.transport.establish_connection()\n           ^^^^^^^^^^^^^^^^^^^^^^^^^^^^^^^^^^^^^\n  File \"/usr/local/lib/python3.11/site-packages/kombu/transport/pyamqp.py\", line 203, in establish_connection\n    conn.connect()\n  File \"/usr/local/lib/python3.11/site-packages/amqp/connection.py\", line 324, in connect\n    self.transport.connect()\n  File \"/usr/local/lib/python3.11/site-packages/amqp/transport.py\", line 129, in connect\n    self._connect(self.host, self.port, self.connect_timeout)\n  File \"/usr/local/lib/python3.11/site-packages/amqp/transport.py\", line 184, in _connect\n    self.sock.connect(sa)\nConnectionRefusedError: [Errno 111] Connection refused\n\nThe above exception was the direct cause of the following exception:\n\nTraceback (most recent call last):\n  File \"/usr/local/lib/python3.11/site-packages/celery/worker/worker.py\", line 202, in start\n    self.blueprint.start(self)\n  File \"/usr/local/lib/python3.11/site-packages/celery/bootsteps.py\", line 112, in start\n    self.on_start()\n  File \"/usr/local/lib/python3.11/site-packages/celery/apps/worker.py\", line 132, in on_start\n    self.purge_messages()\n  File \"/usr/local/lib/python3.11/site-packages/celery/apps/worker.py\", line 187, in purge_messages\n    count = self.app.control.purge(connection=connection)\n            ^^^^^^^^^^^^^^^^^^^^^^^^^^^^^^^^^^^^^^^^^^^^^\n  File \"/usr/local/lib/python3.11/site-packages/celery/app/control.py\", line 467, in purge\n    return self.app.amqp.TaskConsumer(conn).purge()\n           ^^^^^^^^^^^^^^^^^^^^^^^^^^^^^^^^\n  File \"/usr/local/lib/python3.11/site-packages/celery/app/amqp.py\", line 274, in TaskConsumer\n    return self.Consumer(\n           ^^^^^^^^^^^^^^\n  File \"/usr/local/lib/python3.11/site-packages/kombu/messaging.py\", line 402, in __init__\n    self.revive(self.channel)\n  File \"/usr/local/lib/python3.11/site-packages/kombu/messaging.py\", line 415, in revive\n    channel = self.channel = maybe_channel(channel)\n                             ^^^^^^^^^^^^^^^^^^^^^^\n  File \"/usr/local/lib/python3.11/site-packages/kombu/connection.py\", line 1110, in maybe_channel\n    return channel.default_channel\n           ^^^^^^^^^^^^^^^^^^^^^^^\n  File \"/usr/local/lib/python3.11/site-packages/kombu/connection.py\", line 953, in default_channel\n    self._ensure_connection(**conn_opts)\n  File \"/usr/local/lib/python3.11/site-packages/kombu/connection.py\", line 458, in _ensure_connection\n    with ctx():\n  File \"/usr/local/lib/python3.11/contextlib.py\", line 158, in __exit__\n    self.gen.throw(typ, value, traceback)\n  File \"/usr/local/lib/python3.11/site-packages/kombu/connection.py\", line 476, in _reraise_as_library_errors\n    raise ConnectionError(str(exc)) from exc\nkombu.exceptions.OperationalError: [Errno 111] Connection refused"}
alaz-backend-celery-worker-2-1  | 2024-07-10 06:53:53,852 CRITICAL celery.worker Unrecoverable error: OperationalError('[Errno 111] Connection refused')
alaz-backend-celery-worker-2-1  |   File "/usr/local/lib/python3.12/site-packages/kombu/connection.py", line 472, in _reraise_as_library_errors
seaweedfs-1                     | I0710 06:53:39.862774 volume_grpc_client_to_master.go:43 checkWithMaster 172.28.0.7:9333: get master 172.28.0.7:9333 configuration: rpc error: code = Unavailable desc = connection error: desc = "transport: Error while dialing: dial tcp 172.28.0.7:19333: connect: connection refused"
seaweedfs-1                     | I0710 06:53:41.653957 volume_grpc_client_to_master.go:43 checkWithMaster 172.28.0.7:9333: get master 172.28.0.7:9333 configuration: rpc error: code = Unavailable desc = connection error: desc = "transport: Error while dialing: dial tcp 172.28.0.7:19333: connect: connection refused"
seaweedfs-1                     | I0710 06:53:43.445759 volume_grpc_client_to_master.go:43 checkWithMaster 172.28.0.7:9333: get master 172.28.0.7:9333 configuration: rpc error: code = Unavailable desc = connection error: desc = "transport: Error while dialing: dial tcp 172.28.0.7:19333: connect: connection refused"
hammermanager-celery-worker-1   | {"app": "hm", "ddosifyenv": "onprem", "level": "fatal", "time": "2024-07-10T06:54:00Z", "message": "Traceback (most recent call last):\n  File \"/usr/local/lib/python3.11/site-packages/kombu/connection.py\", line 472, in _reraise_as_library_errors\n    yield\n  File \"/usr/local/lib/python3.11/site-packages/kombu/connection.py\", line 459, in _ensure_connection\n    return retry_over_time(\n           ^^^^^^^^^^^^^^^^\n  File \"/usr/local/lib/python3.11/site-packages/kombu/utils/functional.py\", line 318, in retry_over_time\n    return fun(*args, **kwargs)\n           ^^^^^^^^^^^^^^^^^^^^\n  File \"/usr/local/lib/python3.11/site-packages/kombu/connection.py\", line 934, in _connection_factory\n    self._connection = self._establish_connection()\n                       ^^^^^^^^^^^^^^^^^^^^^^^^^^^^\n  File \"/usr/local/lib/python3.11/site-packages/kombu/connection.py\", line 860, in _establish_connection\n    conn = self.transport.establish_connection()\n           ^^^^^^^^^^^^^^^^^^^^^^^^^^^^^^^^^^^^^\n  File \"/usr/local/lib/python3.11/site-packages/kombu/transport/pyamqp.py\", line 203, in establish_connection\n    conn.connect()\n  File \"/usr/local/lib/python3.11/site-packages/amqp/connection.py\", line 324, in connect\n    self.transport.connect()\n  File \"/usr/local/lib/python3.11/site-packages/amqp/transport.py\", line 129, in connect\n    self._connect(self.host, self.port, self.connect_timeout)\n  File \"/usr/local/lib/python3.11/site-packages/amqp/transport.py\", line 184, in _connect\n    self.sock.connect(sa)\nConnectionRefusedError: [Errno 111] Connection refused\n\nThe above exception was the direct cause of the following exception:\n\nTraceback (most recent call last):\n  File \"/usr/local/lib/python3.11/site-packages/celery/worker/worker.py\", line 202, in start\n    self.blueprint.start(self)\n  File \"/usr/local/lib/python3.11/site-packages/celery/bootsteps.py\", line 112, in start\n    self.on_start()\n  File \"/usr/local/lib/python3.11/site-packages/celery/apps/worker.py\", line 132, in on_start\n    self.purge_messages()\n  File \"/usr/local/lib/python3.11/site-packages/celery/apps/worker.py\", line 187, in purge_messages\n    count = self.app.control.purge(connection=connection)\n            ^^^^^^^^^^^^^^^^^^^^^^^^^^^^^^^^^^^^^^^^^^^^^\n  File \"/usr/local/lib/python3.11/site-packages/celery/app/control.py\", line 467, in purge\n    return self.app.amqp.TaskConsumer(conn).purge()\n           ^^^^^^^^^^^^^^^^^^^^^^^^^^^^^^^^\n  File \"/usr/local/lib/python3.11/site-packages/celery/app/amqp.py\", line 274, in TaskConsumer\n    return self.Consumer(\n           ^^^^^^^^^^^^^^\n  File \"/usr/local/lib/python3.11/site-packages/kombu/messaging.py\", line 402, in __init__\n    self.revive(self.channel)\n  File \"/usr/local/lib/python3.11/site-packages/kombu/messaging.py\", line 415, in revive\n    channel = self.channel = maybe_channel(channel)\n                             ^^^^^^^^^^^^^^^^^^^^^^\n  File \"/usr/local/lib/python3.11/site-packages/kombu/connection.py\", line 1110, in maybe_channel\n    return channel.default_channel\n           ^^^^^^^^^^^^^^^^^^^^^^^\n  File \"/usr/local/lib/python3.11/site-packages/kombu/connection.py\", line 953, in default_channel\n    self._ensure_connection(**conn_opts)\n  File \"/usr/local/lib/python3.11/site-packages/kombu/connection.py\", line 458, in _ensure_connection\n    with ctx():\n  File \"/usr/local/lib/python3.11/contextlib.py\", line 158, in __exit__\n    self.gen.throw(typ, value, traceback)\n  File \"/usr/local/lib/python3.11/site-packages/kombu/connection.py\", line 476, in _reraise_as_library_errors\n    raise ConnectionError(str(exc)) from exc\nkombu.exceptions.OperationalError: [Errno 111] Connection refused"}
seaweedfs-1                     | I0710 06:53:45.237232 volume_grpc_client_to_master.go:43 checkWithMaster 172.28.0.7:9333: get master 172.28.0.7:9333 configuration: rpc error: code = Unavailable desc = connection error: desc = "transport: Error while dialing: dial tcp 172.28.0.7:19333: connect: connection refused"
seaweedfs-1                     | I0710 06:53:47.030333 volume_grpc_client_to_master.go:43 checkWithMaster 172.28.0.7:9333: get master 172.28.0.7:9333 configuration: rpc error: code = Unavailable desc = connection error: desc = "transport: Error while dialing: dial tcp 172.28.0.7:19333: connect: connection refused"
backend-celery-beat-1           | {"app": "backend", "anteonenv": "onprem", "level": "fatal", "time": "2024-07-10T06:53:48Z", "message": "Traceback (most recent call last):\n  File \"/usr/local/lib/python3.11/site-packages/django/db/backends/utils.py\", line 89, in _execute\n    return self.cursor.execute(sql, params)\n           ^^^^^^^^^^^^^^^^^^^^^^^^^^^^^^^^\npsycopg2.errors.UndefinedTable: relation \"django_celery_beat_periodictask\" does not exist\nLINE 1: ...ango_celery_beat_periodictask\".\"description\" FROM \"django_ce...\n                                                             ^\n\n\nThe above exception was the direct cause of the following exception:\n\nTraceback (most recent call last):\n  File \"/usr/local/lib/python3.11/site-packages/celery/apps/beat.py\", line 113, in start_scheduler\n    service.start()\n  File \"/usr/local/lib/python3.11/site-packages/celery/beat.py\", line 634, in start\n    humanize_seconds(self.scheduler.max_interval))\n                     ^^^^^^^^^^^^^^\n  File \"/usr/local/lib/python3.11/site-packages/kombu/utils/objects.py\", line 40, in __get__\n    return super().__get__(instance, owner)\n           ^^^^^^^^^^^^^^^^^^^^^^^^^^^^^^^^\n  File \"/usr/local/lib/python3.11/functools.py\", line 1001, in __get__\n    val = self.func(instance)\n          ^^^^^^^^^^^^^^^^^^^\n  File \"/usr/local/lib/python3.11/site-packages/celery/beat.py\", line 677, in scheduler\n    return self.get_scheduler()\n           ^^^^^^^^^^^^^^^^^^^^\n  File \"/usr/local/lib/python3.11/site-packages/celery/beat.py\", line 668, in get_scheduler\n    return symbol_by_name(self.scheduler_cls, aliases=aliases)(\n           ^^^^^^^^^^^^^^^^^^^^^^^^^^^^^^^^^^^^^^^^^^^^^^^^^^^^\n  File \"/usr/local/lib/python3.11/site-packages/django_celery_beat/schedulers.py\", line 226, in __init__\n    Scheduler.__init__(self, *args, **kwargs)\n  File \"/usr/local/lib/python3.11/site-packages/celery/beat.py\", line 264, in __init__\n    self.setup_schedule()\n  File \"/usr/local/lib/python3.11/site-packages/django_celery_beat/schedulers.py\", line 234, in setup_schedule\n    self.install_default_entries(self.schedule)\n                                 ^^^^^^^^^^^^^\n  File \"/usr/local/lib/python3.11/site-packages/django_celery_beat/schedulers.py\", line 356, in schedule\n    self._schedule = self.all_as_schedule()\n                     ^^^^^^^^^^^^^^^^^^^^^^\n  File \"/usr/local/lib/python3.11/site-packages/django_celery_beat/schedulers.py\", line 240, in all_as_schedule\n    for model in self.Model.objects.enabled():\n  File \"/usr/local/lib/python3.11/site-packages/django/db/models/query.py\", line 394, in __iter__\n    self._fetch_all()\n  File \"/usr/local/lib/python3.11/site-packages/django/db/models/query.py\", line 1867, in _fetch_all\n    self._result_cache = list(self._iterable_class(self))\n
              ^^^^^^^^^^^^^^^^^^^^^^^^^^^^^^^^\n  File \"/usr/local/lib/python3.11/site-packages/django/db/models/query.py\", line 87, in __iter__\n    results = compiler.execute_sql(\n              ^^^^^^^^^^^^^^^^^^^^^\n  File \"/usr/local/lib/python3.11/site-packages/django/db/models/sql/compiler.py\", line 1398, in execute_sql\n    cursor.execute(sql, params)\n  File \"/usr/local/lib/python3.11/site-packages/django/db/backends/utils.py\", line 67, in execute\n    return self._execute_with_wrappers(\n
^^^^^^^^^^^^^^^^^^^^^^^^^^^^\n  File \"/usr/local/lib/python3.11/site-packages/django/db/backends/utils.py\", line 80, in _execute_with_wrappers\n    return executor(sql, params, many, context)\n           ^^^^^^^^^^^^^^^^^^^^^^^^^^^^^^^^^^^^\n  File \"/usr/local/lib/python3.11/site-packages/django/db/backends/utils.py\", line 84, in _execute\n    with self.db.wrap_database_errors:\n  File \"/usr/local/lib/python3.11/site-packages/django/db/utils.py\", line 91, in __exit__\n    raise dj_exc_value.with_traceback(traceback) from exc_value\n  File \"/usr/local/lib/python3.11/site-packages/django/db/backends/utils.py\", line 89, in _execute\n    return self.cursor.execute(sql, params)\n           ^^^^^^^^^^^^^^^^^^^^^^^^^^^^^^^^\ndjango.db.utils.ProgrammingError: relation \"django_celery_beat_periodictask\" does not exist\nLINE 1: ...ango_celery_beat_periodictask\".\"description\" FROM \"django_ce...\n                                                             ^\n"}
backend-celery-beat-1           | psycopg2.errors.UndefinedTable: relation "django_celery_beat_periodictask" does not exist
hammermanager-celery-beat-1     | psycopg2.errors.UndefinedTable: relation "django_celery_beat_periodictask" does not exist
backend-1                       |   Applying auth.0007_alter_validators_add_error_messages... OK
hammermanager-1                 |   Applying auth.0007_alter_validators_add_error_messages... OK
seaweedfs-1                     | I0710 06:53:48.821717 volume_grpc_client_to_master.go:43 checkWithMaster 172.28.0.7:9333: get master 172.28.0.7:9333 configuration: rpc error: code = Unavailable desc = connection error: desc = "transport: Error while dialing: dial tcp 172.28.0.7:19333: connect: connection refused"
seaweedfs-1                     | I0710 06:53:50.613287 volume_grpc_client_to_master.go:43 checkWithMaster 172.28.0.7:9333: get master 172.28.0.7:9333 configuration: rpc error: code = Unavailable desc = connection error: desc = "transport: Error while dialing: dial tcp 172.28.0.7:19333: connect: connection refused"
seaweedfs-1                     | I0710 06:53:52.405686 volume_grpc_client_to_master.go:43 checkWithMaster 172.28.0.7:9333: get master 172.28.0.7:9333 configuration: rpc error: code = Unavailable desc = connection error: desc = "transport: Error while dialing: dial tcp 172.28.0.7:19333: connect: connection refused"
seaweedfs-1                     | I0710 06:53:54.196560 volume_grpc_client_to_master.go:43 checkWithMaster 172.28.0.7:9333: get master 172.28.0.7:9333 configuration: rpc error: code = Unavailable desc = connection error: desc = "transport: Error while dialing: dial tcp 172.28.0.7:19333: connect: connection refused"
seaweedfs-1                     | I0710 06:53:55.987752 volume_grpc_client_to_master.go:43 checkWithMaster 172.28.0.7:9333: get master 172.28.0.7:9333 configuration: rpc error: code = Unavailable desc = connection error: desc = "transport: Error while dialing: dial tcp 172.28.0.7:19333: connect: connection refused"
alaz-backend-1                  |   Applying auth.0007_alter_validators_add_error_messages... OK
alaz-backend-celery-worker-1-1  |   File "/usr/local/lib/python3.12/site-packages/kombu/connection.py", line 476, in _reraise_as_library_errors
alaz-backend-celery-worker-2-1  |   File "/usr/local/lib/python3.12/site-packages/kombu/connection.py", line 476, in _reraise_as_library_errors
hammermanager-celery-beat-1     |     with self.db.wrap_database_errors:
hammermanager-celery-beat-1     | psycopg2.errors.UndefinedTable: relation "django_celery_beat_periodictask" does not exist
alaz-backend-celery-beat-1      |     with self.db.wrap_database_errors:
backend-celery-beat-1           |     with self.db.wrap_database_errors:
alaz-backend-celery-beat-1      | beat: Connection error: [Errno 111] Connection refused. Trying again in 2.0 seconds...
alaz-backend-celery-beat-1      | beat: Connection error: [Errno 111] Connection refused. Trying again in 4.0 seconds...
alaz-backend-celery-beat-1      | beat: Connection error: [Errno 111] Connection refused. Trying again in 6.0 seconds...
backend-1                       | {"app": "backend", "anteonenv": "onprem", "level": "error", "time": "2024-07-10T07:34:58Z", "status_code": 500, "message": "Traceback (most recent call last):\n  File \"/usr/local/lib/python3.11/site-packages/asgiref/sync.py\", line 518, in thread_handler\n    raise exc_info[1]\n  File \"/usr/local/lib/python3.11/site-packages/django/core/handlers/exception.py\", line 43, in inner\n    response = await get_response(request)\n               ^^^^^^^^^^^^^^^^^^^^^^^^^^^\n  File \"/usr/local/lib/python3.11/site-packages/asgiref/sync.py\", line 518, in thread_handler\n    raise exc_info[1]\n  File \"/usr/local/lib/python3.11/site-packages/django/core/handlers/base.py\", line 253, in _get_response_async\n    response = await wrapped_callback(\n               ^^^^^^^^^^^^^^^^^^^^^^^\n  File \"/usr/local/lib/python3.11/site-packages/asgiref/sync.py\", line 468, in __call__\n    ret = await asyncio.shield(exec_coro)\n          ^^^^^^^^^^^^^^^^^^^^^^^^^^^^^^^\n  File \"/usr/local/lib/python3.11/site-packages/asgiref/current_thread_executor.py\", line 40, in run\n    result = self.fn(*self.args, **self.kwargs)\n             ^^^^^^^^^^^^^^^^^^^^^^^^^^^^^^^^^^\n  File \"/usr/local/lib/python3.11/site-packages/asgiref/sync.py\", line 522, in thread_handler\n    return func(*args, **kwargs)\n           ^^^^^^^^^^^^^^^^^^^^^\n  File \"/usr/local/lib/python3.11/site-packages/django/views/decorators/csrf.py\", line 55, in wrapped_view\n    return view_func(*args, **kwargs)\n           ^^^^^^^^^^^^^^^^^^^^^^^^^^\n  File \"/usr/local/lib/python3.11/site-packages/django/views/generic/base.py\", line 103, in view\n    return self.dispatch(request, *args, **kwargs)\n           ^^^^^^^^^^^^^^^^^^^^^^^^^^^^^^^^^^^^^^^\n  File \"/usr/local/lib/python3.11/site-packages/rest_framework/views.py\", line 509, in dispatch\n    response = self.handle_exception(exc)\n               ^^^^^^^^^^^^^^^^^^^^^^^^^^\n  File \"/usr/local/lib/python3.11/site-packages/rest_framework/views.py\", line 469, in handle_exception\n    self.raise_uncaught_exception(exc)\n  File \"/usr/local/lib/python3.11/site-packages/rest_framework/views.py\", line 480, in raise_uncaught_exception\n    raise exc\n  File \"/usr/local/lib/python3.11/site-packages/rest_framework/views.py\", line 506, in dispatch\n    response = handler(request, *args, **kwargs)\n               ^^^^^^^^^^^^^^^^^^^^^^^^^^^^^^^^^\n  File \"/workspace/backend/metrics/views.py\", line 110, in get\n    influxdb_response_dict = get_influxdb_response(test=test, get_all=False, request_idx=request_idx)\n
                 ^^^^^^^^^^^^^^^^^^^^^^^^^^^^^^^^^^^^^^^^^^^^^^^^^^^^^^^^^^^^^^^^^^^^^^^^\n  File \"/workspace/backend/metrics/influxdb_utils.py\", line 691, in get_influxdb_response\n    metrics, next_request_idx = query_influxdb(request_idx=request_idx, job_id=job_id, get_all=get_all)\n                                ^^^^^^^^^^^^^^^^^^^^^^^^^^^^^^^^^^^^^^^^^^^^^^^^^^^^^^^^^^^^^^^^^^^^^^^\n  File \"/workspace/backend/metrics/influxdb_utils.py\", line 644, in query_influxdb\n    next_request_idx = i + 1 + request_idx\n                       ^\nUnboundLocalError: cannot access local variable 'i' where it is not associated with a value"}
backend-1                       | {"app": "backend", "anteonenv": "onprem", "level": "error", "time": "2024-07-10T07:34:58Z", "status_code": 500, "message": "Traceback (most recent call last):\n  File \"/usr/local/lib/python3.11/site-packages/asgiref/sync.py\", line 518, in thread_handler\n    raise exc_info[1]\n  File \"/usr/local/lib/python3.11/site-packages/django/core/handlers/exception.py\", line 43, in inner\n    response = await get_response(request)\n               ^^^^^^^^^^^^^^^^^^^^^^^^^^^\n  File \"/usr/local/lib/python3.11/site-packages/asgiref/sync.py\", line 518, in thread_handler\n    raise exc_info[1]\n  File \"/usr/local/lib/python3.11/site-packages/django/core/handlers/base.py\", line 253, in _get_response_async\n    response = await wrapped_callback(\n               ^^^^^^^^^^^^^^^^^^^^^^^\n  File \"/usr/local/lib/python3.11/site-packages/asgiref/sync.py\", line 468, in __call__\n    ret = await asyncio.shield(exec_coro)\n          ^^^^^^^^^^^^^^^^^^^^^^^^^^^^^^^\n  File \"/usr/local/lib/python3.11/site-packages/asgiref/current_thread_executor.py\", line 40, in run\n    result = self.fn(*self.args, **self.kwargs)\n             ^^^^^^^^^^^^^^^^^^^^^^^^^^^^^^^^^^\n  File \"/usr/local/lib/python3.11/site-packages/asgiref/sync.py\", line 522, in thread_handler\n    return func(*args, **kwargs)\n           ^^^^^^^^^^^^^^^^^^^^^\n  File \"/usr/local/lib/python3.11/site-packages/django/views/decorators/csrf.py\", line 55, in wrapped_view\n    return view_func(*args, **kwargs)\n           ^^^^^^^^^^^^^^^^^^^^^^^^^^\n  File \"/usr/local/lib/python3.11/site-packages/django/views/generic/base.py\", line 103, in view\n    return self.dispatch(request, *args, **kwargs)\n           ^^^^^^^^^^^^^^^^^^^^^^^^^^^^^^^^^^^^^^^\n  File \"/usr/local/lib/python3.11/site-packages/rest_framework/views.py\", line 509, in dispatch\n    response = self.handle_exception(exc)\n               ^^^^^^^^^^^^^^^^^^^^^^^^^^\n  File \"/usr/local/lib/python3.11/site-packages/rest_framework/views.py\", line 469, in handle_exception\n    self.raise_uncaught_exception(exc)\n  File \"/usr/local/lib/python3.11/site-packages/rest_framework/views.py\", line 480, in raise_uncaught_exception\n    raise exc\n  File \"/usr/local/lib/python3.11/site-packages/rest_framework/views.py\", line 506, in dispatch\n    response = handler(request, *args, **kwargs)\n               ^^^^^^^^^^^^^^^^^^^^^^^^^^^^^^^^^\n  File \"/workspace/backend/metrics/views.py\", line 110, in get\n    influxdb_response_dict = get_influxdb_response(test=test, get_all=False, request_idx=request_idx)\n
                 ^^^^^^^^^^^^^^^^^^^^^^^^^^^^^^^^^^^^^^^^^^^^^^^^^^^^^^^^^^^^^^^^^^^^^^^^\n  File \"/workspace/backend/metrics/influxdb_utils.py\", line 691, in get_influxdb_response\n    metrics, next_request_idx = query_influxdb(request_idx=request_idx, job_id=job_id, get_all=get_all)\n                                ^^^^^^^^^^^^^^^^^^^^^^^^^^^^^^^^^^^^^^^^^^^^^^^^^^^^^^^^^^^^^^^^^^^^^^^\n  File \"/workspace/backend/metrics/influxdb_utils.py\", line 644, in query_influxdb\n    next_request_idx = i + 1 + request_idx\n                       ^\nUnboundLocalError: cannot access local variable 'i' where it is not associated with a value"}
backend-1                       | {"app": "backend", "anteonenv": "onprem", "level": "error", "time": "2024-07-10T07:40:05Z", "status_code": 500, "message": "Traceback (most recent call last):\n  File \"/usr/local/lib/python3.11/site-packages/asgiref/sync.py\", line 518, in thread_handler\n    raise exc_info[1]\n  File \"/usr/local/lib/python3.11/site-packages/django/core/handlers/exception.py\", line 43, in inner\n    response = await get_response(request)\n               ^^^^^^^^^^^^^^^^^^^^^^^^^^^\n  File \"/usr/local/lib/python3.11/site-packages/asgiref/sync.py\", line 518, in thread_handler\n    raise exc_info[1]\n  File \"/usr/local/lib/python3.11/site-packages/django/core/handlers/base.py\", line 253, in _get_response_async\n    response = await wrapped_callback(\n               ^^^^^^^^^^^^^^^^^^^^^^^\n  File \"/usr/local/lib/python3.11/site-packages/asgiref/sync.py\", line 468, in __call__\n    ret = await asyncio.shield(exec_coro)\n          ^^^^^^^^^^^^^^^^^^^^^^^^^^^^^^^\n  File \"/usr/local/lib/python3.11/site-packages/asgiref/current_thread_executor.py\", line 40, in run\n    result = self.fn(*self.args, **self.kwargs)\n             ^^^^^^^^^^^^^^^^^^^^^^^^^^^^^^^^^^\n  File \"/usr/local/lib/python3.11/site-packages/asgiref/sync.py\", line 522, in thread_handler\n    return func(*args, **kwargs)\n           ^^^^^^^^^^^^^^^^^^^^^\n  File \"/usr/local/lib/python3.11/site-packages/django/views/decorators/csrf.py\", line 55, in wrapped_view\n    return view_func(*args, **kwargs)\n           ^^^^^^^^^^^^^^^^^^^^^^^^^^\n  File \"/usr/local/lib/python3.11/site-packages/django/views/generic/base.py\", line 103, in view\n    return self.dispatch(request, *args, **kwargs)\n           ^^^^^^^^^^^^^^^^^^^^^^^^^^^^^^^^^^^^^^^\n  File \"/usr/local/lib/python3.11/site-packages/rest_framework/views.py\", line 509, in dispatch\n    response = self.handle_exception(exc)\n               ^^^^^^^^^^^^^^^^^^^^^^^^^^\n  File \"/usr/local/lib/python3.11/site-packages/rest_framework/views.py\", line 469, in handle_exception\n    self.raise_uncaught_exception(exc)\n  File \"/usr/local/lib/python3.11/site-packages/rest_framework/views.py\", line 480, in raise_uncaught_exception\n    raise exc\n  File \"/usr/local/lib/python3.11/site-packages/rest_framework/views.py\", line 506, in dispatch\n    response = handler(request, *args, **kwargs)\n               ^^^^^^^^^^^^^^^^^^^^^^^^^^^^^^^^^\n  File \"/workspace/backend/metrics/views.py\", line 110, in get\n    influxdb_response_dict = get_influxdb_response(test=test, get_all=False, request_idx=request_idx)\n
                 ^^^^^^^^^^^^^^^^^^^^^^^^^^^^^^^^^^^^^^^^^^^^^^^^^^^^^^^^^^^^^^^^^^^^^^^^\n  File \"/workspace/backend/metrics/influxdb_utils.py\", line 691, in get_influxdb_response\n    metrics, next_request_idx = query_influxdb(request_idx=request_idx, job_id=job_id, get_all=get_all)\n                                ^^^^^^^^^^^^^^^^^^^^^^^^^^^^^^^^^^^^^^^^^^^^^^^^^^^^^^^^^^^^^^^^^^^^^^^\n  File \"/workspace/backend/metrics/influxdb_utils.py\", line 644, in query_influxdb\n    next_request_idx = i + 1 + request_idx\n                       ^\nUnboundLocalError: cannot access local variable 'i' where it is not associated with a value"}
backend-1                       | {"app": "backend", "anteonenv": "onprem", "level": "error", "time": "2024-07-10T07:40:05Z", "status_code": 500, "message": "Traceback (most recent call last):\n  File \"/usr/local/lib/python3.11/site-packages/asgiref/sync.py\", line 518, in thread_handler\n    raise exc_info[1]\n  File \"/usr/local/lib/python3.11/site-packages/django/core/handlers/exception.py\", line 43, in inner\n    response = await get_response(request)\n               ^^^^^^^^^^^^^^^^^^^^^^^^^^^\n  File \"/usr/local/lib/python3.11/site-packages/asgiref/sync.py\", line 518, in thread_handler\n    raise exc_info[1]\n  File \"/usr/local/lib/python3.11/site-packages/django/core/handlers/base.py\", line 253, in _get_response_async\n    response = await wrapped_callback(\n               ^^^^^^^^^^^^^^^^^^^^^^^\n  File \"/usr/local/lib/python3.11/site-packages/asgiref/sync.py\", line 468, in __call__\n    ret = await asyncio.shield(exec_coro)\n          ^^^^^^^^^^^^^^^^^^^^^^^^^^^^^^^\n  File \"/usr/local/lib/python3.11/site-packages/asgiref/current_thread_executor.py\", line 40, in run\n    result = self.fn(*self.args, **self.kwargs)\n             ^^^^^^^^^^^^^^^^^^^^^^^^^^^^^^^^^^\n  File \"/usr/local/lib/python3.11/site-packages/asgiref/sync.py\", line 522, in thread_handler\n    return func(*args, **kwargs)\n           ^^^^^^^^^^^^^^^^^^^^^\n  File \"/usr/local/lib/python3.11/site-packages/django/views/decorators/csrf.py\", line 55, in wrapped_view\n    return view_func(*args, **kwargs)\n           ^^^^^^^^^^^^^^^^^^^^^^^^^^\n  File \"/usr/local/lib/python3.11/site-packages/django/views/generic/base.py\", line 103, in view\n    return self.dispatch(request, *args, **kwargs)\n           ^^^^^^^^^^^^^^^^^^^^^^^^^^^^^^^^^^^^^^^\n  File \"/usr/local/lib/python3.11/site-packages/rest_framework/views.py\", line 509, in dispatch\n    response = self.handle_exception(exc)\n               ^^^^^^^^^^^^^^^^^^^^^^^^^^\n  File \"/usr/local/lib/python3.11/site-packages/rest_framework/views.py\", line 469, in handle_exception\n    self.raise_uncaught_exception(exc)\n  File \"/usr/local/lib/python3.11/site-packages/rest_framework/views.py\", line 480, in raise_uncaught_exception\n    raise exc\n  File \"/usr/local/lib/python3.11/site-packages/rest_framework/views.py\", line 506, in dispatch\n    response = handler(request, *args, **kwargs)\n               ^^^^^^^^^^^^^^^^^^^^^^^^^^^^^^^^^\n  File \"/workspace/backend/metrics/views.py\", line 110, in get\n    influxdb_response_dict = get_influxdb_response(test=test, get_all=False, request_idx=request_idx)\n
                 ^^^^^^^^^^^^^^^^^^^^^^^^^^^^^^^^^^^^^^^^^^^^^^^^^^^^^^^^^^^^^^^^^^^^^^^^\n  File \"/workspace/backend/metrics/influxdb_utils.py\", line 691, in get_influxdb_response\n    metrics, next_request_idx = query_influxdb(request_idx=request_idx, job_id=job_id, get_all=get_all)\n                                ^^^^^^^^^^^^^^^^^^^^^^^^^^^^^^^^^^^^^^^^^^^^^^^^^^^^^^^^^^^^^^^^^^^^^^^\n  File \"/workspace/backend/metrics/influxdb_utils.py\", line 644, in query_influxdb\n    next_request_idx = i + 1 + request_idx\n                       ^\nUnboundLocalError: cannot access local variable 'i' where it is not associated with a value"}
hammermanager-celery-beat-1     |     with self.db.wrap_database_errors:
hammermanager-celery-beat-1     | beat: Connection error: [Errno 111] Connection refused. Trying again in 2.0 seconds...
hammermanager-celery-beat-1     | beat: Connection error: [Errno 111] Connection refused. Trying again in 4.0 seconds...